<mujoco>
  <compiler angle="radian" meshdir="./mesh" texturedir="./textures" inertiafromgeom="true"/>
  <option integrator="implicitfast"/>

  <worldbody>
    <body name="Chassis" pos="0.0018212049035355449 0.0 0.0" quat="1.0 0.0 0.0 0.0">
      <inertial mass="0.70" pos="0.0 0.0 0.0"/>
      <geom type="mesh" name="Chassis geom" mesh="Chassis" rgba="1.0 1.0 1.0 1.0" />
      <joint type="free" name="floating_joint"/>

      <body name="Battery" pos="-0.04232122004032135 0.0 0.0031644522678107023" quat="1.0 0.0 0.0 0.0">
        <inertial mass="0.59" pos="0.0 0.0 0.0"/>
        <geom type="mesh" name="Battery geom" mesh="Battery" rgba="1.0 1.0 1.0 1.0" />
      </body>
      <body name="Display" pos="0.05479276552796364 0.0 0.08916442096233368" quat="1.0 0.0 0.0 0.0">
        <inertial mass="0.55" pos="0.0 0.0 0.0"/>
        <geom type="mesh" name="Display geom" mesh="Display" rgba="1.0 1.0 1.0 1.0" />
      </body>
      <body name="Driver" pos="-0.0018212107243016362 0.0 -0.11049394309520721" quat="1.0 0.0 0.0 0.0">
        <inertial mass="0.40" pos="0.0 0.0 0.0"/>
        <geom type="mesh" name="Driver geom" mesh="Driver" rgba="1.0 1.0 1.0 1.0" />
      </body>
      <body name="Glass" pos="0.012068401090800762 0.0 0.02563333325088024" quat="1.0 0.0 0.0 0.0">
        <inertial mass="1.450" pos="0.0 0.0 0.0"/>
        <geom type="mesh" name="Glass geom" mesh="Glass" rgba="1.0 1.0 1.0 1.0" />
      </body>


      <body name="IMU" pos="-0.001821218873374164 0.0 -0.10333554446697235" quat="1.0 0.0 0.0 0.0">
        <geom type="mesh" name="IMU geom" mesh="Sphere" rgba="1.0 1.0 1.0 1.0" />
        <site name="FRAME"/>
      </body>


      <body name="Motors" pos="-0.0018212789436802268 0.0 -0.19233578443527222" quat="1.0 0.0 0.0 0.0">
        <inertial mass="2.26" pos="0.0 0.0 0.0"/>
        <geom type="mesh" name="Motors geom" mesh="Motors" rgba="1.0 1.0 1.0 1.0" />
      </body>
      <body name="Supports" pos="-0.001821270794607699 0.0 -0.16840942203998566" quat="1.0 0.0 0.0 0.0">
        <geom type="mesh" name="Supports geom" mesh="Supports" rgba="1.0 1.0 1.0 1.0" />
      </body>
      <body name="STM" pos="-0.001821214915253222 0.0 -0.12298552691936493" quat="1.0 0.0 0.0 0.0">
        <inertial mass="0.07" pos="0.0 0.0 0.0"/>
        <geom type="mesh" name="STM geom" mesh="STM" rgba="1.0 1.0 1.0 1.0" />
      </body>

      <body name="WheelL" pos="-0.0017285948852077127 0.1490991711616516 -0.19225578010082245" quat="0.7071067094802856 0.70710688829422 0.0 0.0">
        <inertial mass="0.134" pos="0.0 0.0 0.0" diaginertia="0.00014 0.00014 0.00026"/>
        <joint name="left_wheel_joint" type="hinge" axis="0 0 1" damping="0.2" armature="5.3e-05"/>
        <geom type="mesh" name="WheelL_visual" mesh="WheelL" rgba="1 1 1 1" contype="0" conaffinity="0"/>
        <geom type="cylinder" name="WheelL_collision" pos="0 0 0" size="0.0625 0.01" rgba="0.8 0.2 0.2 0.3" contype="1" conaffinity="1" friction="0.8 0.05 0.002"/>
      </body>

      <body name="WheelR" pos="-0.0017284463392570615 -0.14910069108009338 -0.192415252327919" quat="0.7071067094802856 0.70710688829422 0.0 0.0">
        <inertial mass="0.134" pos="0.0 0.0 0.0"/>
        <joint name="right_wheel_joint" type="hinge" axis="0 0 1" damping="0.2" armature="5.3e-05"/>
        <geom type="mesh" name="WheelR_visual" mesh="WheelR" rgba="1 1 1 1" contype="0" conaffinity="0"/>
        <geom type="cylinder" name="WheelR_collision" pos="0 0 0" size="0.0625 0.01" rgba="0.8 0.2 0.2 0.3" contype="1" conaffinity="1" friction="0.8 0.05 0.002"/>
      </body>

    </body>
  </worldbody>

  <contact>
    <exclude body1="Chassis" body2="WheelL"/>
    <exclude body1="Chassis" body2="WheelR"/>
  </contact>

  <asset>
    <mesh name="Chassis" file="Chassis.obj"/>
    <mesh name="Battery" file="Battery.obj"/>
    <mesh name="Display" file="Display.obj"/>
    <mesh name="Driver" file="Driver.obj"/>
    <mesh name="Glass" file="Glass.obj"/>
    <mesh name="Sphere" file="Sphere.obj"/>
    <mesh name="WheelL" file="WheelL.obj"/>
    <mesh name="Motors" file="Motors.obj"/>
    <mesh name="WheelR" file="WheelR.obj"/>
    <mesh name="STM" file="STM.obj"/>
    <mesh name="Supports" file="Supports.obj"/>
  </asset>

  <actuator>
    <velocity name="left_motor" joint="left_wheel_joint"
              ctrlrange="-8.775 8.775"
              forcerange="-2.5 2.5"
              kv="20"
              ctrllimited="true"
              forcelimited="true"/>
    <velocity name="right_motor" joint="right_wheel_joint"
              ctrlrange="-8.775 8.775"
              forcerange="-2.5 2.5"
              kv="20"
              ctrllimited="true"
              forcelimited="true"/>
  </actuator>

  <sensor>
    <!-- Real data for observation -->
    <!--  Indices 0, 1, 2-->
    <accelerometer noise="0.04" site="FRAME" name="accelerometer"/> <!-- 0.04 m/s^2 -->
    
    <!-- Indices 3, 4, 5 -->
    <gyro noise="0.00175" site="FRAME" name="gyroscope"/> <!-- 0.05 °/s -> 0.00175 rad/s -->
    
    <!-- Indices 6, 7 -->
    <jointpos name="left_wheel_pos" joint="left_wheel_joint"/>
    <jointpos name="right_wheel_pos" joint="right_wheel_joint"/>
    
    <!--  Ideal data for reward computation -->
    <!-- Indices 8, 9 -->
    <jointvel name="left_wheel_vel" joint="left_wheel_joint"/>
    <jointvel name="right_wheel_vel" joint="right_wheel_joint"/>
    <!-- Indices 10, 11, 12 -->
    <accelerometer site="FRAME" name="ideal_accelerometer"/>
    <!-- Indices 13, 14, 15 -->
    <gyroscope site="FRAME" name="ideal_gyroscope"/>
  </sensor>

</mujoco>
